<?xml version="1.0" encoding="utf-8"?>
<!-- This URDF was automatically created by SolidWorks to URDF Exporter! Originally created by Stephen Brawner (brawner@gmail.com) 
     Commit Version: 1.6.0-4-g7f85cfe  Build Version: 1.6.7995.38578
     For more information, please see http://wiki.ros.org/sw_urdf_exporter -->
<robot
  name="finalbot">
  <link
    name="base_link">
    <inertial>
      <origin
        xyz="-0.012984546417506 0.00386031982659382 0.0028150193347373"
        rpy="0 0 0" />
      <mass
        value="3.12447110718362" />
      <inertia
        ixx="0.0101765622751055"
        ixy="-8.33475054187552E-06"
        ixz="-0.000407885130932817"
        iyy="0.0140735401654392"
        iyz="-1.47424116291273E-06"
        izz="0.022527449194129" />
    </inertial>
    <visual>
      <origin
        xyz="0 0 0"
        rpy="0 0 0" />
      <geometry>
        <mesh
          filename="package://finalbot/meshes/base_link.STL" />
      </geometry>
      <material
        name="">
        <color
          rgba="0.968627450980392 0.258823529411765 0.258823529411765 1" />
      </material>
    </visual>
    <collision>
      <origin
        xyz="0 0 0"
        rpy="0 0 0" />
      <geometry>
        <mesh
          filename="package://finalbot/meshes/base_link.STL" />
      </geometry>
    </collision>
  </link>
  <link
    name="leftwheel">
    <inertial>
      <origin
        xyz="2.77555756156289E-17 -1.72084568816899E-15 0.246029171631938"
        rpy="0 0 0" />
      <mass
        value="0.015766987148019" />
      <inertia
        ixx="6.40297333602334E-06"
        ixy="8.10930579044381E-22"
        ixz="-7.81778316863285E-23"
        iyy="6.40297333602334E-06"
        iyz="-3.00885561986696E-20"
        izz="1.06004642486074E-05" />
    </inertial>
    <visual>
      <origin
        xyz="0 0 0"
        rpy="0 0 0" />
      <geometry>
        <mesh
          filename="package://finalbot/meshes/leftwheel.STL" />
      </geometry>
      <material
        name="">
        <color
          rgba="0.294117647058824 0.294117647058824 0.294117647058824 1" />
      </material>
    </visual>
    <collision>
      <origin
        xyz="0 0 0"
        rpy="0 0 0" />
      <geometry>
        <mesh
          filename="package://finalbot/meshes/leftwheel.STL" />
      </geometry>
    </collision>
  </link>
  <joint
    name="leftwheel"
    type="continuous">
    <origin
      xyz="0.158895590614314 -0.125767330164326 -0.0235253402197184"
      rpy="-1.5707963267949 0 0" />
    <parent
      link="base_link" />
    <child
      link="leftwheel" />
    <axis
      xyz="0 0 -1" />
    <limit
      effort="10"
      velocity="10" />
    <dynamics
      damping="0.1"
      friction="0.1" />
  </joint>
  <link
    name="rightwheel">
    <inertial>
      <origin
        xyz="2.77555756156289E-17 -9.71445146547012E-17 0.0131708281800618"
        rpy="0 0 0" />
      <mass
        value="0.015766987148019" />
      <inertia
        ixx="6.40297333602335E-06"
        ixy="1.32891326813347E-21"
        ixz="1.28691576492E-21"
        iyy="6.40297333602334E-06"
        iyz="-2.96995504735356E-20"
        izz="1.06004642486074E-05" />
    </inertial>
    <visual>
      <origin
        xyz="0 0 0"
        rpy="0 0 0" />
      <geometry>
        <mesh
          filename="package://finalbot/meshes/rightwheel.STL" />
      </geometry>
      <material
        name="">
        <color
          rgba="0.294117647058824 0.294117647058824 0.294117647058824 1" />
      </material>
    </visual>
    <collision>
      <origin
        xyz="0 0 0"
        rpy="0 0 0" />
      <geometry>
        <mesh
          filename="package://finalbot/meshes/rightwheel.STL" />
      </geometry>
    </collision>
  </link>
  <joint
    name="rightwheel"
    type="continuous">
    <origin
      xyz="0.158895590614314 -0.125767330164326 -0.0235253402197184"
      rpy="-1.5707963267949 0 0" />
    <parent
      link="base_link" />
    <child
      link="rightwheel" />
    <axis
      xyz="0 0 -1" />
    <limit
      effort="10"
      velocity="10" />
    <dynamics
      damping="1"
      friction="1" />
  </joint>
</robot>