<?xml version="1.0" encoding="utf-8"?>
<!-- This URDF was automatically created by SolidWorks to URDF Exporter! Originally created by Stephen Brawner (brawner@gmail.com) 
     Commit Version: 1.6.0-4-g7f85cfe  Build Version: 1.6.7995.38578
     For more information, please see http://wiki.ros.org/sw_urdf_exporter -->
<robot
  name="Assemurdf">
  <link
    name="base_link">
    <inertial>
      <origin
        xyz="-0.012984546417506 0.00386031982659382 0.0028150193347373"
        rpy="0 0 0" />
      <mass
        value="3.12447110718362" />
      <inertia
        ixx="0.0101765622751055"
        ixy="-8.33475054187555E-06"
        ixz="-0.000407885130932817"
        iyy="0.0140735401654392"
        iyz="-1.47424116291273E-06"
        izz="0.022527449194129" />
    </inertial>
    <visual>
      <origin
        xyz="0 0 0"
        rpy="0 0 0" />
      <geometry>
        <mesh
          filename="package://Assemurdf/meshes/base_link.STL" />
      </geometry>
      <material
        name="">
        <color
          rgba="0.792156862745098 0.819607843137255 0.933333333333333 1" />
      </material>
    </visual>
    <collision>
      <origin
        xyz="0 0 0"
        rpy="0 0 0" />
      <geometry>
        <mesh
          filename="package://Assemurdf/meshes/base_link.STL" />
      </geometry>
    </collision>
  </link>
  <link
    name="leftwheel">
    <inertial>
      <origin
        xyz="2.77555756156289E-17 -1.72084568816899E-15 0.24671810745511"
        rpy="0 0 0" />
      <mass
        value="0.0154842443751589" />
      <inertia
        ixx="6.32949606004192E-06"
        ixy="8.10885382994361E-22"
        ixz="-7.75313443278777E-23"
        iyy="6.32949606004192E-06"
        iyz="-3.0598357474165E-20"
        izz="1.06002362306982E-05" />
    </inertial>
    <visual>
      <origin
        xyz="0 0 0"
        rpy="0 0 0" />
      <geometry>
        <mesh
          filename="package://Assemurdf/meshes/leftwheel.STL" />
      </geometry>
      <material
        name="">
        <color
          rgba="0.294117647058824 0.294117647058824 0.294117647058824 1" />
      </material>
    </visual>
    <collision>
      <origin
        xyz="0 0 0"
        rpy="0 0 0" />
      <geometry>
        <mesh
          filename="package://Assemurdf/meshes/leftwheel.STL" />
      </geometry>
    </collision>
  </link>
  <joint
    name="leftwheel"
    type="continuous">
    <origin
      xyz="0.1589 -0.12577 -0.023525"
      rpy="-1.5708 0 0" />
    <parent
      link="base_link" />
    <child
      link="leftwheel" />
    <axis
      xyz="0 0 -1" />
    <limit
      effort="10"
      velocity="10" />
    <dynamics
      damping="0.1"
      friction="0.1" />
  </joint>
  <link
    name="rightwheel">
    <inertial>
      <origin
        xyz="0 -8.32667268468867E-17 0.0124818923568899"
        rpy="0 0 0" />
      <mass
        value="0.0154842443751589" />
      <inertia
        ixx="6.32949606004192E-06"
        ixy="1.32770758776718E-21"
        ixz="1.29112806876612E-21"
        iyy="6.32949606004192E-06"
        iyz="-3.02088668473641E-20"
        izz="1.06002362306982E-05" />
    </inertial>
    <visual>
      <origin
        xyz="0 0 0"
        rpy="0 0 0" />
      <geometry>
        <mesh
          filename="package://Assemurdf/meshes/rightwheel.STL" />
      </geometry>
      <material
        name="">
        <color
          rgba="0.294117647058824 0.294117647058824 0.294117647058824 1" />
      </material>
    </visual>
    <collision>
      <origin
        xyz="0 0 0"
        rpy="0 0 0" />
      <geometry>
        <mesh
          filename="package://Assemurdf/meshes/rightwheel.STL" />
      </geometry>
    </collision>
  </link>
  <joint
    name="rightwheel"
    type="continuous">
    <origin
      xyz="0.1589 -0.12577 -0.023525"
      rpy="-1.5708 0 0" />
    <parent
      link="base_link" />
    <child
      link="rightwheel" />
    <axis
      xyz="0 0 -1" />
    <limit
      effort="10"
      velocity="10" />
    <dynamics
      damping="1"
      friction="1" />
  </joint>
</robot>