<?xml version="1.0" encoding="utf-8"?>
<!-- This URDF was automatically created by SolidWorks to URDF Exporter! Originally created by Stephen Brawner (brawner@gmail.com) 
     Commit Version: 1.6.0-4-g7f85cfe  Build Version: 1.6.7995.38578
     For more information, please see http://wiki.ros.org/sw_urdf_exporter -->
<robot
  name="Assem5">
  <link
    name="base_link">
    <inertial>
      <origin
        xyz="-0.0519027671846017 2.7645074374652E-05 0.0312601129481959"
        rpy="0 0 0" />
      <mass
        value="3.12503740346226" />
      <inertia
        ixx="0.0101802209294379"
        ixy="-8.32731972476421E-06"
        ixz="-0.000407868204595875"
        iyy="0.0140826384459327"
        iyz="-1.47425502690866E-06"
        izz="0.0225402056092829" />
    </inertial>
    <visual>
      <origin
        xyz="0 0 0"
        rpy="0 0 0" />
      <geometry>
        <mesh
          filename="package://Assem5/meshes/base_link.STL" />
      </geometry>
      <material
        name="">
        <color
          rgba="0.792156862745098 0.819607843137255 0.933333333333333 1" />
      </material>
    </visual>
    <collision>
      <origin
        xyz="0 0 0"
        rpy="0 0 0" />
      <geometry>
        <mesh
          filename="package://Assem5/meshes/base_link.STL" />
      </geometry>
    </collision>
  </link>
  <link
    name="left_wheel">
    <inertial>
      <origin
        xyz="0.119946229458579 -0.117198107643109 0.00492452483658509"
        rpy="0 0 0" />
      <mass
        value="0.0154842443751589" />
      <inertia
        ixx="6.32949606004192E-06"
        ixy="2.91175550249844E-22"
        ixz="-8.82281936056068E-23"
        iyy="1.06002362306982E-05"
        iyz="2.70221847327768E-23"
        izz="6.32949606004191E-06" />
    </inertial>
    <visual>
      <origin
        xyz="0 0 0"
        rpy="0 0 0" />
      <geometry>
        <mesh
          filename="package://Assem5/meshes/left_wheel.STL" />
      </geometry>
      <material
        name="">
        <color
          rgba="0.752941176470588 0.752941176470588 0.752941176470588 1" />
      </material>
    </visual>
    <collision>
      <origin
        xyz="0 0 0"
        rpy="0 0 0" />
      <geometry>
        <mesh
          filename="package://Assem5/meshes/left_wheel.STL" />
      </geometry>
    </collision>
  </link>
  <joint
    name="left_wheelj"
    type="continuous">
    <origin
      xyz="0 0 0"
      rpy="0 0 0" />
    <parent
      link="base_link" />
    <child
      link="left_wheel" />
    <axis
      xyz="0 -1 0" />
  </joint>
  <link
    name="right_wheel">
    <inertial>
      <origin
        xyz="0.119946222993201 0.117198107643112 0.00492452660000059"
        rpy="0 0 0" />
      <mass
        value="0.0154842443751589" />
      <inertia
        ixx="6.3294960600419E-06"
        ixy="-8.72737624636687E-22"
        ixz="1.80070720815117E-22"
        iyy="1.06002362306982E-05"
        iyz="3.01996515628913E-20"
        izz="6.3294960600419E-06" />
    </inertial>
    <visual>
      <origin
        xyz="0 0 0"
        rpy="0 0 0" />
      <geometry>
        <mesh
          filename="package://Assem5/meshes/right_wheel.STL" />
      </geometry>
      <material
        name="">
        <color
          rgba="0.752941176470588 0.752941176470588 0.752941176470588 1" />
      </material>
    </visual>
    <collision>
      <origin
        xyz="0 0 0"
        rpy="0 0 0" />
      <geometry>
        <mesh
          filename="package://Assem5/meshes/right_wheel.STL" />
      </geometry>
    </collision>
  </link>
  <joint
    name="right_wheelj"
    type="continuous">
    <origin
      xyz="0 0 0"
      rpy="0 0 0" />
    <parent
      link="base_link" />
    <child
      link="right_wheel" />
    <axis
      xyz="0 1 0" />
  </joint>
</robot>